Workbook
Name Slicer_NAMA_KELAS: #N/A
Name Slicer_RUTE: #N/A
Name Slicer_STATUS_BAGASI: #N/A

Sheet Data Diri (Wajib Diisi)
I1: 🎓 UNJUK KETERAMPILAN MICROSOFT EXCEL BATCH 8 🎓
I11: Mohon lengkapi data berikut untuk kepentingan E-Certificate!
I13: Nama | J13: Daffa Farros Azhari
I14: No. WhatsApp / ID Telegram | J14: 85604054640
I15: E-mail | J15: azharidaffa18@gmail.com
I18: Catatan: Untuk mengisi nomor whatsapp dan id telegram pilih salah satu jika masuk ke salah satu grup diskusi, dan isi keduanya jika masuk ke kedua grup diskusi

Sheet Data Acuan
A1: 🎓 UNJUK KETERAMPILAN MICROSOFT EXCEL BATCH 8 🎓
A6: Kasus - Sistem Informasi Penerbangan Maskapai Ruyi Air | L6: INSTRUKSI PENGERJAAN: | Y6: INSTRUKSI PENGERJAAN:
A7: Ilustrasi Soal: | L7: Petunjuk Umum (Mengisi Sheet Jawaban): | Y7: Petunjuk Umum (Pembuatan Pivot Table + Chart):
A8: Maskapai Ruyi Air memiliki sistem informasi penerbangan yang digunakan untuk mencatat data penumpang, kode tiket, jadwal penerbangan, kelas kursi, serta perhitungan biaya tambahan bagasi. Saat ini, data masih tersimpan dalam beberapa tabel referensi terpisah. Untuk menghasilkan laporan biaya penumpang yang otomatis, akurat, dan konsisten, diperlukan pengolahan data menggunakan rumus Excel, khususnya: VLOOKUP, HLOOKUP, IF (Logika). Peserta ujian diminta menyusun rumus Excel tanpa input manual nilai, serta tidak mengubah struktur tabel referensi. | L8: ● | M8: Gunakan data pada Sheet Jawaban untuk mengisi kolom jawaban. | Y8: Gunakan data transaksi penerbangan yang ada di Sheet Jawaban untuk membuat laporan ringkasan dalam bentuk 3 Pivot Table dan 3 Pivot Chart yang saling terhubung.
L9: ● | M9: Ambil data referensi dari Sheet Data Acuan.
L10: ● | M10: Pastikan menggunakan Absolute Reference ($) pada setiap rumus yang merujuk ke tabel referensi.
Y11: 1 | Z11: Analisis Pendapatan Per Rute dan Kelas
L12: 1 | M12: RUTE | Z12: Soal ini bertujuan untuk melihat kontribusi setiap kelas terhadap total pendapatan di tiap rute.
M13: Isi kolom rute berdasarkan Kode Penerbangan yang diambil dari kolom Kode Tiket, dengan mengacu pada tabel referensi di Sheet Data Acuan. | Z13: ● | AA13: Instruksi: Buatlah Pivot Table yang menampilkan Total Biaya berdasarkan Rute dan Nama Kelas. ㅡ Pengaturan Field Pivot Table: Rute (Row), Nama Kelas (Columns), Sum of Total Biaya (Values).
L15: 2 | M15: JAM BERANGKAT | Z15: ● | AA15: Format: Ubah format angka menjadi Accounting (Rp) tanpa desimal.
M16: Isi kolom jam berangkat berdasarkan Kode Penerbangan yang diambil dari kolom Kode Tiket, dengan mengacu pada tabel referensi di Sheet Data Acuan. | Z16: ● | AA16: Pivot Chart: Gunakan grafik Stacked Column Chart (Grafik Batang Bertumpuk). Ketentuan Chart, sebagai berikut: - Judul Chart: Analisis Total Pendapatan per Rute dan Kelas Penerbangan - Munculkan Label Data (Data Labels) dan Legend (Keterangan Warna) menampilkan Nama Kelas (Business, Economy, First Class) tetap dimunculkan agar tahu mewakili kelas apa. - Nama Sumbu Horisontal (X-Axis): Rute - Nama Sumbu Vertikal (Y-Axis): Nilai Rupiah (Total Biaya)
A17: TABEL REFERENSI
A18: 1) REFERENSI PENERBANGAN | G18: 2) REFERENSI KELAS KURSI | L18: 3 | M18: JAM TIBA
A19: Kode Penerbangan | B19: Rute | C19: Jam Berangkat | D19: Jam Tiba | E19: Harga Dasar | G19: Kode Kelas | H19: E | I19: B | J19: F | M19: Isi kolom jam tiba berdasarkan Kode Penerbangan yang diambil dari kolom Kode Tiket, dengan mengacu pada tabel referensi di Sheet Data Acuan.
G20: Nama Kelas | H20: Economy | I20: Business | J20: First Class
A21: NA101 | B21: Jakarta – Bali | C21: 0.25 | D21: 0.33333333 | E21: 1200000 | G21: Faktor Harga | H21: 1 | I21: 1.5 | J21: 2 | L21: 4 | M21: DURASI
A22: NA102 | B22: Jakarta – Surabaya | C22: 0.3125 | D22: 0.375 | E22: 900000 | M22: Hitung selisih antara Jam Tiba dan Jam Berangkat.
A23: NA103 | B23: Jakarta – Medan | C23: 0.33333333 | D23: 0.4375 | E23: 1500000 | M23: Catatan: Pastikan format sel adalah Time (hh:mm). | Y23: 2 | Z23: Laporan Volume Penumpang dan Status Bagasi
A24: NA104 | B24: Jakarta – Makassar | C24: 0.375 | D24: 0.47916667 | E24: 1800000 | L24: 5 | M24: HARGA DASAR | Z24: Soal ini menguji kemampuan peserta dalam melakukan penghitungan jumlah data (Counting) dan memilah kategori layanan.
A25: NA105 | B25: Jakarta – Lombok | C25: 0.41666667 | D25: 0.5 | E25: 1300000 | M25: Isi kolom harga dasar berdasarkan Kode Penerbangan yang diambil dari kolom Kode Tiket, dengan mengacu pada tabel referensi di Sheet Data Acuan.
Z26: ● | AA26: Instruksi: Buatlah Pivot Table yang menampilkan Jumlah Penumpang berdasarkan Rute dan Status Bagasi. ㅡ Pengaturan Field Pivot Table: Rute (Row), Status Bagasi (Columns), Count of Nama Penumpang (Values).
L27: 6 | M27: NAMA KELAS
M28: Isi kolom nama kelas berdasarkan Kode Kelas yang diambil dari 1 karakter terakhir di kolom Kode Tiket, dengan mengacu pada tabel referensi kelas di Sheet Data Acuan. | Z28: ● | AA28: Penting: Pastikan pada bagian Value Field Settings dipilih Count, bukan Sum.
Z29: ● | AA29: Pivot Chart: Gunakan grafik Clustered Bar Chart (Grafik Batang Horisontal). Ketentuan Chart, sebagai berikut: - Judul Chart: Distribusi Status Bagasi Penumpang per Rute - Munculkan Label Data (Data Labels) dan Legend (Keteragan Warna) menampilkan kategori Status Bayar (Berbayar dan Gratis) tetap dimunculkan. - Nama Sumbu Horisontal (X-Axis): Rute - Nama Sumbu Vertikal (Y-Axis): Jumlah (Count)
L30: 7 | M30: FAKTOR HARGA
M31: Isi kolom faktor harga berdasarkan Kode Kelas yang diambil dari 1 karakter terakhir di kolom Kode Tiket, dengan mengacu pada tabel referensi kelas di Sheet Data Acuan.
M33: Catatan: Faktor Harga adalah angka pengali (koefisien) yang digunakan untuk menentukan harga akhir tiket berdasarkan kelas kursi yang dipilih oleh penumpang. Dalam sistem database, faktor ini berfungsi sebagai indeks pembeda nilai antara layanan standar dan layanan premium.
Y35: 3 | Z35: Analisis Efisiensi Jarak dan Durasi Terbang
L36: 8 | M36: HARGA TIKET KELAS | Z36: Soal ini berfokus pada data operasional penerbangan.
M37: Isi kolom harga tiket kelas dengan mengalikan kolom Harga Dasar dengan kolom Faktor Harga. | Z37: ● | AA37: Instruksi: Buatlah Pivot Table yang menampilkan Rata-rata Durasi terbang untuk setiap kategori Status Jarak. ㅡ Pengaturan Field Pivot Table: Status Jarak (Row), Avarage of Durasi (Values).
L38: 9 | M38: TARIF BAGASI TAMBAHAN
M39: Isi kolom besarnya tarif tambahan bagasi berdasarkan Berat Bagasi, dengan ketentuan sebagai berikut: - Jika berat bagasi lebih besar sama dengan 40 kg, maka tarif bagasi tambahan sebesar Rp 800.000. - Jika lebih besar sama dengan 35 kg, maka Rp 500.000. - Jika lebih besar sama dengan 30 kg, maka Rp 300.000. - Jika lebih besar sama dengan 25 kg, maka Rp 150.000. - Jika berat di bawah 25 kg, maka tidak dikenakan biaya tambahan (Rp 0). | Z39: ● | AA39: Penting: Ubah pengaturan Value Field Settings menjadi Average (Rata-rata) dan pastikan format sel tetap Time (hh:mm). Cara mengubah menjadi format Time, sebagai berikut: Cara Pertama: - Di salah satu rata-rata durasi klik kanan, kemudian pilih Value Field Settings... - Klik tombol Number Format yang terletak di pojok kiri bawah jendela Value Field Settings. - Pada jendela Format Cells, pilih kategori Time di kolom sebelah kiri. - Pilih tipe format jam yang diinginkan, disarankan menggunakan format 13:30 atau hh:mm agar tampilan jam dan menit terlihat jelas. Jika pilihan format jam tidak tersedia, bisa pilih kategori Custom dan masukan format hh:mm. - Klik OK pada jendela Format Cells, lalu klik OK sekali lagi pada jendela Value Field Settings. Contoh hasilnya akan menjadi 01:30. Cara Kedua: - Blok kolom hasil avarage rata-rata, kemudian klik Ctrl + 1. - Pada jendela Format Cells, pilih kategori Time di kolom sebelah kiri. - Pilih tipe format jam yang diinginkan, disarankan menggunakan format 13:30 atau hh:mm agar tampilan jam dan menit terlihat jelas. Jika pilihan format jam tidak tersedia, bisa pilih kategori Custom dan masukan format hh:mm. - Klik OK. Contoh hasilnya akan menjadi 01:30.
L45: 10 | M45: TOTAL BIAYA
M46: Isi kolom total biaya dengan menjumlahkan kolom Harga Tiket Kelas dengan kolom Tarif Tambahan Bagasi.
L47: 11 | M47: STATUS BAGASI
M48: Isi kolom status bagasi, dengan ketentuan: - Jika berat bagasi penumpang di bawah atau sama dengan 20 kg, maka berikan status "Gratis". - Jika lebih dari itu, berikan status "Berbayar".
L51: 12 | M51: STATUS JARAK
M52: Gunakan fungsi IF yang dikombinasikan dengan fungsi TIME untuk menentukan status jarak, dengan ketentuan: - Jika Durasi terbang lebih dari 01:30:00 (1 jam 30 menit), maka statusnya adalah "Jarak Jauh". - Jika tidak, maka statusnya "Jarak Dekat".
Z58: ● | AA58: Pivot Chart: Gunakan Pie Chart. Ketentuan Chart, sebagai berikut: - Judul Chart: Perbandingan Rata-rata Durasi Terbang - Munculkan Label Data (Data Labels) Value & Percentase dan Legend (Keteragan Warna) menampilkan keterangan Jarak Dekat dan Jarak Jauh. (Pastikan format labelnya adalah Time (hh:mm), contohnya: 01:30 dan 02:15. Jangan biarkan dalam bentuk desimal 0,06 atau 0,09).
Y63: 4 | Z63: Pembuatan Slicer
...

Sheet Jawaban
A1: DATA TRANSAKSI PENUMPANG MASKAPAI RUYI AIR
A2: Periode: Januari 2026
A5: NO | B5: KODE TIKET | C5: NAMA PENUMPANG | D5: TANGGAL TERBANG | E5: BERAT BAGASI (Kg) | F5: RUTE | G5: JAM BERANGKAT | H5: JAM TIBA | I5: DURASI | J5: HARGA DASAR | K5: NAMA KELAS | L5: FAKTOR HARGA | M5: HARGA TIKET KELAS | N5: TARIF BAGASI TAMBAHAN | O5: TOTAL BIAYA | P5: STATUS BAGASI | Q5: STATUS JARAK
A6: 1 | B6: BK001-NA101-E | C6: LOKA WIRANTA | D6: 46023 | E6: 18 | F6: =VLOOKUP(MID(B6,7,5),'Data Acuan'!$A$19:$E$25,2,0) -> Jakarta – Bali | G6: =VLOOKUP(MID(B6,7,5),'Data Acuan'!$A$19:$E$25,3,0) -> 0.25 | H6: =VLOOKUP(MID(B6,7,5),'Data Acuan'!$A$19:$E$25,4,0) -> 0.33333333 | I6: =H6-G6 -> 0.083333333 | J6: =VLOOKUP(MID(B6,7,5),'Data Acuan'!$A$19:$E$25,5,0) -> 1200000 | K6: =RIGHT(B6,1) -> E | L6: =HLOOKUP(K6,'Data Acuan'!$H$19:$J$21,3,0) -> 1 | M6: =J6*L6 -> 1200000 | N6: =IF(E6>=40,"800000",IF(E6>=35,"500000",IF(E6>=30,"300000",IF(E6>=25,"150000","0")))) -> 0 | O6: =M6+N6 -> 1200000 | P6: =IF(E6<=20,"Gratis","Berbayar") -> Gratis | Q6: =IF(I6>TIME(1,30,0),"Jarak Jauh","Jarak Dekat") -> Jarak Jauh
A7: 2 | B7: BK002-NA102-B | C7: HANA LIN | D7: 46023 | E7: 22 | F7: =VLOOKUP(MID(B7,7,5),'Data Acuan'!$A$19:$E$25,2) -> Jakarta – Surabaya | G7: =VLOOKUP(MID(B7,7,5),'Data Acuan'!$A$19:$E$25,3,0) -> 0.3125 | H7: =VLOOKUP(MID(B7,7,5),'Data Acuan'!$A$19:$E$25,4,0) -> 0.375 | I7: =H7-G7 -> 0.0625 | J7: =VLOOKUP(MID(B7,7,5),'Data Acuan'!$A$19:$E$25,5,0) -> 900000 | K7: =RIGHT(B7,1) -> B | L7: =HLOOKUP(K7,'Data Acuan'!$H$19:$J$21,3,0) -> 1.5 | M7: =J7*L7 -> 1350000 | N7: =IF(E7>=40,"800000",IF(E7>=35,"500000",IF(E7>=30,"300000",IF(E7>=25,"150000","0")))) -> 0 | O7: =M7+N7 -> 1350000 | P7: =IF(E7<=20,"Gratis","Berbayar") -> Berbayar | Q7: =IF(I7>TIME(1,30,0),"Jarak Jauh","Jarak Dekat") -> Jarak Dekat
A8: 3 | B8: BK003-NA103-E | C8: SANITA VELORA | D8: 46024 | E8: 20 | F8: =VLOOKUP(MID(B8,7,5),'Data Acuan'!$A$19:$E$25,2) -> Jakarta – Medan | G8: =VLOOKUP(MID(B8,7,5),'Data Acuan'!$A$19:$E$25,3,0) -> 0.33333333 | H8: =VLOOKUP(MID(B8,7,5),'Data Acuan'!$A$19:$E$25,4,0) -> 0.4375 | I8: =H8-G8 -> 0.10416667 | J8: =VLOOKUP(MID(B8,7,5),'Data Acuan'!$A$19:$E$25,5,0) -> 1500000 | K8: =RIGHT(B8,1) -> E | L8: =HLOOKUP(K8,'Data Acuan'!$H$19:$J$21,3,0) -> 1 | M8: =J8*L8 -> 1500000 | N8: =IF(E8>=40,"800000",IF(E8>=35,"500000",IF(E8>=30,"300000",IF(E8>=25,"150000","0")))) -> 0 | O8: =M8+N8 -> 1500000 | P8: =IF(E8<=20,"Gratis","Berbayar") -> Gratis | Q8: =IF(I8>TIME(1,30,0),"Jarak Jauh","Jarak Dekat") -> Jarak Jauh
A9: 4 | B9: BK004-NA104-F | C9: VANYA RUSELINA | D9: 46024 | E9: 30 | F9: =VLOOKUP(MID(B9,7,5),'Data Acuan'!$A$19:$E$25,2) -> Jakarta – Makassar | G9: =VLOOKUP(MID(B9,7,5),'Data Acuan'!$A$19:$E$25,3,0) -> 0.375 | H9: =VLOOKUP(MID(B9,7,5),'Data Acuan'!$A$19:$E$25,4,0) -> 0.47916667 | I9: =H9-G9 -> 0.10416667 | J9: =VLOOKUP(MID(B9,7,5),'Data Acuan'!$A$19:$E$25,5,0) -> 1800000 | K9: =RIGHT(B9,1) -> F | L9: =HLOOKUP(K9,'Data Acuan'!$H$19:$J$21,3,0) -> 2 | M9: =J9*L9 -> 3600000 | N9: =IF(E9>=40,"800000",IF(E9>=35,"500000",IF(E9>=30,"300000",IF(E9>=25,"150000","0")))) -> 300000 | O9: =M9+N9 -> 3900000 | P9: =IF(E9<=20,"Gratis","Berbayar") -> Berbayar | Q9: =IF(I9>TIME(1,30,0),"Jarak Jauh","Jarak Dekat") -> Jarak Jauh
A10: 5 | B10: BK005-NA105-B | C10: REZA TARMOKO | D10: 46025 | E10: 27 | F10: =VLOOKUP(MID(B10,7,5),'Data Acuan'!$A$19:$E$25,2) -> Jakarta – Lombok | G10: =VLOOKUP(MID(B10,7,5),'Data Acuan'!$A$19:$E$25,3,0) -> 0.41666667 | H10: =VLOOKUP(MID(B10,7,5),'Data Acuan'!$A$19:$E$25,4,0) -> 0.5 | I10: =H10-G10 -> 0.083333333 | J10: =VLOOKUP(MID(B10,7,5),'Data Acuan'!$A$19:$E$25,5,0) -> 1300000 | K10: =RIGHT(B10,1) -> B | L10: =HLOOKUP(K10,'Data Acuan'!$H$19:$J$21,3,0) -> 1.5 | M10: =J10*L10 -> 1950000 | N10: =IF(E10>=40,"800000",IF(E10>=35,"500000",IF(E10>=30,"300000",IF(E10>=25,"150000","0")))) -> 150000 | O10: =M10+N10 -> 2100000 | P10: =IF(E10<=20,"Gratis","Berbayar") -> Berbayar | Q10: =IF(I10>TIME(1,30,0),"Jarak Jauh","Jarak Dekat") -> Jarak Jauh
A11: 6 | B11: BK006-NA101-E | C11: DARGO MAWESTA | D11: 46025 | E11: 15 | F11: =VLOOKUP(MID(B11,7,5),'Data Acuan'!$A$19:$E$25,2) -> Jakarta – Bali | G11: =VLOOKUP(MID(B11,7,5),'Data Acuan'!$A$19:$E$25,3,0) -> 0.25 | H11: =VLOOKUP(MID(B11,7,5),'Data Acuan'!$A$19:$E$25,4,0) -> 0.33333333 | I11: =H11-G11 -> 0.083333333 | J11: =VLOOKUP(MID(B11,7,5),'Data Acuan'!$A$19:$E$25,5,0) -> 1200000 | K11: =RIGHT(B11,1) -> E | L11: =HLOOKUP(K11,'Data Acuan'!$H$19:$J$21,3,0) -> 1 | M11: =J11*L11 -> 1200000 | N11: =IF(E11>=40,"800000",IF(E11>=35,"500000",IF(E11>=30,"300000",IF(E11>=25,"150000","0")))) -> 0 | O11: =M11+N11 -> 1200000 | P11: =IF(E11<=20,"Gratis","Berbayar") -> Gratis | Q11: =IF(I11>TIME(1,30,0),"Jarak Jauh","Jarak Dekat") -> Jarak Jauh
A12: 7 | B12: BK007-NA102-F | C12: TISYA AVENDRA | D12: 46026 | E12: 35 | F12: =VLOOKUP(MID(B12,7,5),'Data Acuan'!$A$19:$E$25,2) -> Jakarta – Surabaya | G12: =VLOOKUP(MID(B12,7,5),'Data Acuan'!$A$19:$E$25,3,0) -> 0.3125 | H12: =VLOOKUP(MID(B12,7,5),'Data Acuan'!$A$19:$E$25,4,0) -> 0.375 | I12: =H12-G12 -> 0.0625 | J12: =VLOOKUP(MID(B12,7,5),'Data Acuan'!$A$19:$E$25,5,0) -> 900000 | K12: =RIGHT(B12,1) -> F | L12: =HLOOKUP(K12,'Data Acuan'!$H$19:$J$21,3,0) -> 2 | M12: =J12*L12 -> 1800000 | N12: =IF(E12>=40,"800000",IF(E12>=35,"500000",IF(E12>=30,"300000",IF(E12>=25,"150000","0")))) -> 500000 | O12: =M12+N12 -> 2300000 | P12: =IF(E12<=20,"Gratis","Berbayar") -> Berbayar | Q12: =IF(I12>TIME(1,30,0),"Jarak Jauh","Jarak Dekat") -> Jarak Dekat
A13: 8 | B13: BK008-NA103-E | C13: KARYO LIMANTARA | D13: 46026 | E13: 21 | F13: =VLOOKUP(MID(B13,7,5),'Data Acuan'!$A$19:$E$25,2) -> Jakarta – Medan | G13: =VLOOKUP(MID(B13,7,5),'Data Acuan'!$A$19:$E$25,3,0) -> 0.33333333 | H13: =VLOOKUP(MID(B13,7,5),'Data Acuan'!$A$19:$E$25,4,0) -> 0.4375 | I13: =H13-G13 -> 0.10416667 | J13: =VLOOKUP(MID(B13,7,5),'Data Acuan'!$A$19:$E$25,5,0) -> 1500000 | K13: =RIGHT(B13,1) -> E | L13: =HLOOKUP(K13,'Data Acuan'!$H$19:$J$21,3,0) -> 1 | M13: =J13*L13 -> 1500000 | N13: =IF(E13>=40,"800000",IF(E13>=35,"500000",IF(E13>=30,"300000",IF(E13>=25,"150000","0")))) -> 0 | O13: =M13+N13 -> 1500000 | P13: =IF(E13<=20,"Gratis","Berbayar") -> Berbayar | Q13: =IF(I13>TIME(1,30,0),"Jarak Jauh","Jarak Dekat") -> Jarak Jauh
A14: 9 | B14: BK009-NA104-B | C14: JEFRO MALANTARA | D14: 46027 | E14: 25 | F14: =VLOOKUP(MID(B14,7,5),'Data Acuan'!$A$19:$E$25,2) -> Jakarta – Makassar | G14: =VLOOKUP(MID(B14,7,5),'Data Acuan'!$A$19:$E$25,3,0) -> 0.375 | H14: =VLOOKUP(MID(B14,7,5),'Data Acuan'!$A$19:$E$25,4,0) -> 0.47916667 | I14: =H14-G14 -> 0.10416667 | J14: =VLOOKUP(MID(B14,7,5),'Data Acuan'!$A$19:$E$25,5,0) -> 1800000 | K14: =RIGHT(B14,1) -> B | L14: =HLOOKUP(K14,'Data Acuan'!$H$19:$J$21,3,0) -> 1.5 | M14: =J14*L14 -> 2700000 | N14: =IF(E14>=40,"800000",IF(E14>=35,"500000",IF(E14>=30,"300000",IF(E14>=25,"150000","0")))) -> 150000 | O14: =M14+N14 -> 2850000 | P14: =IF(E14<=20,"Gratis","Berbayar") -> Berbayar | Q14: =IF(I14>TIME(1,30,0),"Jarak Jauh","Jarak Dekat") -> Jarak Jauh
A15: 10 | B15: BK010-NA105-F | C15: BINAR KENDARTA | D15: 46027 | E15: 40 | F15: =VLOOKUP(MID(B15,7,5),'Data Acuan'!$A$19:$E$25,2) -> Jakarta – Lombok | G15: =VLOOKUP(MID(B15,7,5),'Data Acuan'!$A$19:$E$25,3,0) -> 0.41666667 | H15: =VLOOKUP(MID(B15,7,5),'Data Acuan'!$A$19:$E$25,4,0) -> 0.5 | I15: =H15-G15 -> 0.083333333 | J15: =VLOOKUP(MID(B15,7,5),'Data Acuan'!$A$19:$E$25,5,0) -> 1300000 | K15: =RIGHT(B15,1) -> F | L15: =HLOOKUP(K15,'Data Acuan'!$H$19:$J$21,3,0) -> 2 | M15: =J15*L15 -> 2600000 | N15: =IF(E15>=40,"800000",IF(E15>=35,"500000",IF(E15>=30,"300000",IF(E15>=25,"150000","0")))) -> 800000 | O15: =M15+N15 -> 3400000 | P15: =IF(E15<=20,"Gratis","Berbayar") -> Berbayar | Q15: =IF(I15>TIME(1,30,0),"Jarak Jauh","Jarak Dekat") -> Jarak Jauh
A16: 11 | B16: BK011-NA101-E | C16: CHIKA YURESTA | D16: 46028 | E16: 19 | F16: =VLOOKUP(MID(B16,7,5),'Data Acuan'!$A$19:$E$25,2) -> Jakarta – Bali | G16: =VLOOKUP(MID(B16,7,5),'Data Acuan'!$A$19:$E$25,3,0) -> 0.25 | H16: =VLOOKUP(MID(B16,7,5),'Data Acuan'!$A$19:$E$25,4,0) -> 0.33333333 | I16: =H16-G16 -> 0.083333333 | J16: =VLOOKUP(MID(B16,7,5),'Data Acuan'!$A$19:$E$25,5,0) -> 1200000 | K16: =RIGHT(B16,1) -> E | L16: =HLOOKUP(K16,'Data Acuan'!$H$19:$J$21,3,0) -> 1 | M16: =J16*L16 -> 1200000 | N16: =IF(E16>=40,"800000",IF(E16>=35,"500000",IF(E16>=30,"300000",IF(E16>=25,"150000","0")))) -> 0 | O16: =M16+N16 -> 1200000 | P16: =IF(E16<=20,"Gratis","Berbayar") -> Gratis | Q16: =IF(I16>TIME(1,30,0),"Jarak Jauh","Jarak Dekat") -> Jarak Jauh
A17: 12 | B17: BK012-NA102-B | C17: MEI ZHANG | D17: 46028 | E17: 28 | F17: =VLOOKUP(MID(B17,7,5),'Data Acuan'!$A$19:$E$25,2) -> Jakarta – Surabaya | G17: =VLOOKUP(MID(B17,7,5),'Data Acuan'!$A$19:$E$25,3,0) -> 0.3125 | H17: =VLOOKUP(MID(B17,7,5),'Data Acuan'!$A$19:$E$25,4,0) -> 0.375 | I17: =H17-G17 -> 0.0625 | J17: =VLOOKUP(MID(B17,7,5),'Data Acuan'!$A$19:$E$25,5,0) -> 900000 | K17: =RIGHT(B17,1) -> B | L17: =HLOOKUP(K17,'Data Acuan'!$H$19:$J$21,3,0) -> 1.5 | M17: =J17*L17 -> 1350000 | N17: =IF(E17>=40,"800000",IF(E17>=35,"500000",IF(E17>=30,"300000",IF(E17>=25,"150000","0")))) -> 150000 | O17: =M17+N17 -> 1500000 | P17: =IF(E17<=20,"Gratis","Berbayar") -> Berbayar | Q17: =IF(I17>TIME(1,30,0),"Jarak Jauh","Jarak Dekat") -> Jarak Dekat
A18: 13 | B18: BK013-NA103-F | C18: LIU SHISHI | D18: 46029 | E18: 33 | F18: =VLOOKUP(MID(B18,7,5),'Data Acuan'!$A$19:$E$25,2) -> Jakarta – Medan | G18: =VLOOKUP(MID(B18,7,5),'Data Acuan'!$A$19:$E$25,3,0) -> 0.33333333 | H18: =VLOOKUP(MID(B18,7,5),'Data Acuan'!$A$19:$E$25,4,0) -> 0.4375 | I18: =H18-G18 -> 0.10416667 | J18: =VLOOKUP(MID(B18,7,5),'Data Acuan'!$A$19:$E$25,5,0) -> 1500000 | K18: =RIGHT(B18,1) -> F | L18: =HLOOKUP(K18,'Data Acuan'!$H$19:$J$21,3,0) -> 2 | M18: =J18*L18 -> 3000000 | N18: =IF(E18>=40,"800000",IF(E18>=35,"500000",IF(E18>=30,"300000",IF(E18>=25,"150000","0")))) -> 300000 | O18: =M18+N18 -> 3300000 | P18: =IF(E18<=20,"Gratis","Berbayar") -> Berbayar | Q18: =IF(I18>TIME(1,30,0),"Jarak Jauh","Jarak Dekat") -> Jarak Jauh
... A55: 50 | B55: BK050-NA105-E | C55: ZHANG BICHEN | D55: 46053 | E55: 16 | F55: =VLOOKUP(MID(B55,7,5),'Data Acuan'!$A$19:$E$25,2) -> Jakarta – Lombok | G55: =VLOOKUP(MID(B55,7,5),'Data Acuan'!$A$19:$E$25,3,0) -> 0.41666667 | H55: =VLOOKUP(MID(B55,7,5),'Data Acuan'!$A$19:$E$25,4,0) -> 0.5 | I55: =H55-G55 -> 0.083333333 | J55: =VLOOKUP(MID(B55,7,5),'Data Acuan'!$A$19:$E$25,5,0) -> 1300000 | K55: =RIGHT(B55,1) -> E | L55: =HLOOKUP(K55,'Data Acuan'!$H$19:$J$21,3,0) -> 1 | M55: =J55*L55 -> 1300000 | N55: =IF(E55>=40,"800000",IF(E55>=35,"500000",IF(E55>=30,"300000",IF(E55>=25,"150000","0")))) -> 0 | O55: =M55+N55 -> 1300000 | P55: =IF(E55<=20,"Gratis","Berbayar") -> Gratis | Q55: =IF(I55>TIME(1,30,0),"Jarak Jauh","Jarak Dekat") -> Jarak Jauh

Sheet Pivot Table Chart
A1: Jawaban Pivot Table:
A3: Sum of TOTAL BIAYA | B3: NAMA KELAS | F3: Sum of TOTAL BIAYA
A4: RUTE | B4: Business | C4: Economy | D4: First Class | F4: 109900000
A5: Jakarta – Bali | B5: 3750000 | C5: 6000000 | D5: 9000000
A6: Jakarta – Lombok | B6: 8250000 | C6: 3900000 | D6: 9900000 | F6: Row Labels | G6: Sum of TOTAL BIAYA
A7: Jakarta – Makassar | B7: 8550000 | C7: 5400000 | D7: 16800000 | F7: BUSINESS | G7: 33600000 | H7: =INDEX(F7:F9,MATCH(MAX(G7:G9),G7:G9,0)) -> FIRST CLASS
A8: Jakarta – Medan | B8: 7200000 | C8: 6000000 | D8: 10100000 | F8: ECONOMY | G8: 24000000
A9: Jakarta – Surabaya | B9: 5850000 | C9: 2700000 | D9: 6500000 | F9: FIRST CLASS | G9: 52300000
F11: Average of DURASI
A12: Count of NAMA PENUMPANG | B12: Column Labels | F12: 0.0875
A13: Row Labels | B13: Berbayar | C13: Gratis
A14: Jakarta – Bali | B14: 5 | C14: 5
A15: Jakarta – Lombok | B15: 7 | C15: 3
A16: Jakarta – Makassar | B16: 7 | C16: 3
A17: Jakarta – Medan | B17: 7 | C17: 3
A18: Jakarta – Surabaya | B18: 7 | C18: 3
A21: Row Labels | B21: Average of DURASI
A22: Jarak Dekat | B22: 0.0625
A23: Jarak Jauh | B23: 0.09375

Sheet Dashboard
